# promise/async/await
## 1. async的语法糖
异步函数内部同时利用了生成器和Promise
```js
async function example(a, b, c) {
  // 函数体
}
```

其实是
```js
function example (a, b, c) {
  return spawn(function*() {
    // 函数体
  });
}
```

```js
  function spawn(generator) {
    // 将所有代码包装在一个Promise中
    return new Promise((resolve, reject) => {
      const g = generator();
      // 运行第一步
      step(() => g.next());

      function runNext(nextFn) {
        try {
          // 继续执行生成器代码
          return nextFn();

        } catch (err) {
          // 以失败告终，拒绝当前Promise
          reject(err);
        }
      }
      function step(nextFn) {
        const next = runNext(nextFn);
        if (next.done) {
          resolve(next.value);
          return;
        }
        // 未结束，连缀返回的Promise并运行下一步
        Promise.resolve(next.value)
        .then((value) => step(() => g.next(value)), err => step(() => g.throw(err)));
      }
    })
  }
```

### async捕获错误问题
当有多个错误，并做不同处理时，try catch导致代码杂乱。
解决：await 后的promise对象添加catch函数
```js
function to (promise) {
  return promise.then(data => {
    return [null, data];
  }).catch(err => [err]);
}

// 伪代码，调用
async function asyncTask() {
  let err, user, savedTask;
  [err, user] = await to(UseModel.findById(1));
  if (!user) {
    throw new Error('No user found');
  }
  [err, savedTask] = await to(TaskModel({userId: 1}));
  if (err) throw new Error('Error');
}
```





## 2. Promise的超时机制
利用Promise.race
```js
function delayPromise(ms) {
  return new Promise((resolve) => {
    setTimeout(resolve, ms);
  });
}

function timeoutPromise(promise, ms) {
  const timeout = delayPromise(ms).then(() => {
    throw New Error('operation timed out after' + ms + 'ms');
  });
  return Promise.race([promise, timeout]);
}

// 使用
const taskPromise = new Promise((resolve) => {
  const delay = Math.random() * 2000;
  setTimeout(() => {
    resolve(delay + 'ms');
  }, delay);
});
timeoutPromise(taskPromise, 1000).then((value) => {
  console.log('规定时间内结束');
}).catch(() => {
  console.log('超时');
});
```

### 2.1 实现一个Promise注意事项
1. 同步任务：利用setTimeout特性将resolve和reject具体执行放到then之后
2. 三种状态：then方法里对三种状态做判断
3. 支持链式操作：then方法里最后返回this
4. 支持串行异步任务：每个回调函数注册在对应的异步操作promise的onFulfilledCallback里。令then最后返回一个新promise


#### 2.1.1 第一版
```js
function Promise(executor) {
    let _this = this;
    // 默认状态
    _this.status = 'pending';
    // 成功传递的数据
    _this.value = undefined;
    // 失败传递的原因
    _this.reason = undefined;

    function resolve(value) {
        // 只有pedding才可转其他状态
        if (_this.statsu === 'pedding') {
            _this.status = 'resolve';
            _this.value = value;
        }
    }
    function reject(reason) {
        if (_this.status === 'pendding') {
            _this.status = 'rejected';
            _this.reason = reason;
        }
    }
    edeutor(resolve, reject);
}
Promise.prototype.then = function(onFulfilled, onRejected) {
    let _this = this;
    if (_this.status === 'resolved') {
        onFulfilled(_this.value);
    }
    if (_this.status === 'rejected') {
        onRejected(_this.reason);
    }
}
```
**问题**：回调立即执行，无法异步。

```js
let p = new Promise(function(resolve, reject) {
    setTimeout(function() {
        reslove();
    }, 1000);
});
p.then(function(data) {
    console.log('成功', data);
}, function(err) {
    console.log('失败', err);
})
// 不会输出
```
then方法执行时，Promise的状态还没有改变，还是pedding，异步代码应把回调进行缓存。


#### 2.1.2 第二版
```js
function Promise(executor) {
    let _this = this;
    // 默认状态
    _this.status = 'pending';
    // 成功传递的数据
    _this.value = undefined;
    // 失败传递的原因
    _this.reason = undefined;

    // 存then成功回调
    _this.onResolvedCallbacks = [];
    // 存then失败回调
    _this.onRejectedCallbacks = [];

    function resolve(value) {
        // 只有pedding才可转其他状态
        if (_this.statsu === 'pedding') {
            _this.status = 'resolve';
            _this.value = value;
            _this.onResolvedCallbacks.forEach(function(fn) {
                fn();
            });
        }
    }

    function reject(reason) {
        if (_this.status === 'pendding') {
            _this.status = 'rejected';
            _this.reason = reason;
            _this.onRejectedCallbacks.forEach(function(fn) {
                fn();
            });
        }
    }

    try {
        executor(resolve, reject);
    } catch(e) {
        reject(e);
    }
}

Promise.prototype.then = function(onFulfilled, onRejected) {
    let _this = this;
    if (_this.status === 'resolved') {
        onFulfilled(_this.value);
    }
    if (_this.status === 'rejected') {
        onRejected(_this.reason);
    }
    if (_this.status === 'pedding') {
        // 如果是等待状态，回调push进数组，等状态改变再执行
        _this.onResolvedCallbacks.push(function() {
            onFulfilled(_this.value);
        });
        _this.onRejectedCallbacks.push(function() {
            onRejected(_this.reason);
        });
    }
}

```
**问题**：链式调用（难），返回一个新的promise
1. 前次then返回普通值，字符串数组对象
2. 前次then返回一个promise，需判断到底返回什么...
3. 前次then返回一个Promise，有异步操作，等状态改变，再进行下面操作；
4. 前次then返回自己本身这个promise；
5. 前次一个假promise，可能也有then；
6. 调用resolve时候再传一个promise，还要处理这个promise.
    ```js
        p.then(function(data) {
            return new Promise(resolve, reject) {
                resolve(new Promise(function(resolve, reject) {
                    resolve(11);
                }));
            });
        });
    ```
7. 既调resolve,又调reject，忽略后一个；
8. 光then，什么也不写；
问题1-7：统一定义函数resolvePromise解决。


#### 2.1.3 第三版
```js
// 其他一样
Promise.prototype.then = function(onFulfilled, onRejected) {
    // 成功or失败不传给函数，fix问题8
    onFulfilled = typeof onFulfilled === 'function' ? onFulfilled: function(value) {
        return value;
    };

    onRejected = typeof onRejected === 'function' ? onRejected: function(err) {
        throw err;
    };

    let _this = this;
    // 返回的promise
    let promise2;
    if (_this.status === 'resolved') {
        promise2 = new Promise(function(resolve, reject) {
            // 当成功or失败执行时有异常那么返回的promies应是失败
            setTimeout(function() {
                try {
                    let x = onFulfilled(_this.value);
                    // 统一处理问题1-7
                    resolvePromise(promise2, x, resolve, reject);
                } catch (e) {
                    reject(e);
                }
            });
        });
    }

    if (_this.status === 'rejected') {
        promise2 = new Promise(function() {
             /**
             * 为什么resolve和reject要加setTimeout?
             * 2.2.4规范 onFulfilled 和 onRejected 只允许在 execution context 栈仅包含平台代码时运行.
             * 注1 这里的平台代码指的是引擎、环境以及 promise 的实施代码。实践中要确保 onFulfilled 和 onRejected 方法异步执行，且应该在 then 方法被调   用的那一轮事件循环之后的新执行栈中执行。
             * 这个事件队列可以采用“宏任务（macro-task）”机制，比如setTimeout 或者 setImmediate； 也可以采用“微任务（micro-task）”机制来实现， 比如 MutationObserver 或者process.nextTick。
             */
            setTimeout(function() {
                try {
                    let x = onRejected(_this.reason);
                    reslovePromise(promie2, x, resolve, reject);
                } catch (e) {
                    reject(e);
                }
            });
        });
    }

    if (_this.status === 'pendding') {
        promise2 = new Promise(function(resolve, reject) {
            _this.onResolveCallbacks.push(function() {
                setTimeout(function() {
                    try {
                        let x = onFulfilled(_this.value);
                        resolvePromise(promise2, x, resolve, reject);
                    } catch (e) {
                        reject(e);
                    }
                });
            });
            _this.onRejectedCallbacks.push(function() {
                setTimeout(function() {
                    try {
                        let x = onRejected(_this.reason);
                        resolvePromise(promise2, x, resolve, reject);
                    } catch(e) {
                        reject(e);
                    }
                });
            });
        })
    }
    return promise2;
}

function resolvePromies(promise2, x, resolve, reject) {
    // 新promise，返回值，成功和失败回调
    // 可能x是别人的promise，允许其他乱写
    // 修复问题4
    if (promise2 === x) {
        return reject(new TypeError('循环引用'));
    }
    // 看x是不是promise，promise应该是对象
    // 是否调过成功or失败，修复问题7
    let called;
    // 判断上一次then返回的普通值or函数，修复问题1/2
    if (x !=== null && (typeof x === 'object' || typeof x === 'function')) {
        // 可能是promise，有then方法就认为是
        try {
            let then = x.then;
            if (typeof then === 'function') {
                // 如果还是promise，可当下一次x使用
                // 用call修改指针为x
                then.call(x, function(y) {
                    if (called) return;
                    called = true;
                    // y可能是promise，去解析知道返回的是一个普通值, 修复问题6
                    resolvePromise(promise2, y, resolve, reject);
                }, function(err) {
                    if (called) return;
                    called = true;
                    reject(err);
                });
            } else {
                resolve(x);
            }
        } catch (e) {
            if (called) return;
            called = true;
            reject(e);
        }
    } else {
        // 说明是普通值，修复问题1
        resolve(x);
    }
}
Promise.prototype.catch = function (callback) {
    return this.then(null, callback);
}

Promise.resolve = function(value) {
    return new Promise(resolve, reject) {
        resolve(value);
    };
}
```

#### 2.1.4 官方规范
To run[[Resolve]] (promise, x)，
1. if promise and x refer to the same object, reject promise with a TypeError as the reason.
2. If x is a promise, adopt its state:

    1. if x is pending, promise must remian pending until x is fulfilled or rejected.
    2. if/when x is fulfilled, fulfill promise with the same value.
    3. if/when x is rejected, reject promise with the same reason.
3. 否则，if x is a object or function:

    1. let then be x.then
    2. if retrieving the property x.then results in a thrown exception e. reject promise with e as the reason.
    3. if then is a function, call it with x as this, first argument resolve promise, and second argument rejectedPromise, where:
        * a) if/when resolvePromise is called with a value y, run [[Resolve]](promise, y).
        * b) if/when rejectPromise is called with a reason r, reject promise with r.
        * c) if both resolvePromise and rejectPromise are clled, or multiple calls to the same arguments are made, the first call takes precedence, and any further calls are ignore.
        * d) if calling throw an exception:
            1. if resolvePromise or rejectPromise have been called, ignore it.
            2. otherwise, reject promise with e as the reason.
    4. if then is not a function, fulfill promise with x.
4. if x is not an object or function, fulfill promise with x.








### 2.2 实现Promise.finally?
```js
Promise.prototype.finally = function(callback) {
  let p = this.constructor;
  return this.then(
    value => p.resolve(callback()).then(() => value),
    reason => p.resolve(callback()).then(() => {
      throw reason;
    });
  )
}
```

### 2.3 Promise解决的问题
1. 嵌套问题
2. 控制反转再反转：
* 回调函数执行多次：Promise只能resolve一次
* 回调函数没有执行：用Promise.race解决(超时机制)
* 回调有时同步有时异步：同步异步共存情况无法保证程序逻辑的一致性，而Promise解决了这个问题。

#### 回调地狱的问题
不单单是嵌套和缩进
1. 难以复用：引用了外层变量，牵一发而动全身；
2. 堆栈信息被断开：
A调用了B.A函数的执行上下文压入栈中，再给B的执行上下文压入栈中。当B执行完，B出栈，A执行完，A出栈。
中断代码，可以搜索完整的堆栈信息。
异步回调并非如此。直到主线程完成，才从任务队列中选择已完成任务，加入栈中，栈中只有一个执行上下文，回调报错，是无法获取调用该异步操作时的栈中信息。不容易判定哪里出错。（promise也没解决这个问题）

## 3. 异步迭代生成器
```js
let it;

function foo(x, y) {
  ajax('http://xxx', function(err, data) {
    if (err) {
      it.throw(err);
    } else {
      it.next(data);
    }
  });
}

function *main() {
  try {
    // 暂停
    // 请求成功，it.next()
    // 赋给text
    const text = yield foo(11, 31);
    console.log(text);
  } catch(err) {
    ...
  }
}
// 调用
it = main();
it.next();
```
优点：
1. 抽象了异步;
2. 同步形式追踪流程控制;
3. 同步捕获异步错误;

#### 生成器 + Promise
```js
function *main {
  // 同上
}
function foo(x, y) {
  return request('http://url'); // 一个promise
}

// 调用
const it = main();;
const p = it.next().value;
p.then(function(text) {
  it.next();
}, function(err) {
  it.throw(err);
})
```

#### async与await
```js
function foo(x, y) {
  // 一样
}

async function main() {
  try {
    const text = await foo(11, 31);
    console.log(text);
  } catch(err) {
    console.log(err);
  }
}

// 调用
main();
```
#### 举例
2个请求并发，都完成后请求第3个；
```js
function *foo() {
  const p1 = request("http://url1");
  const p2 = request("http://url2");
  const r1 = yield p1;
  const r2 = yield p2;
  const r3 = yield request("http://url3");
  console.log(r3);
}
```
更简化：
```js
function bar(url1, url2) {
  return Promise.all([
    request(url1),
    request(url2)
  ]);
}

function *foo() {
  // 隐藏promise并发细节
  const result = yield bar("http://url1", "http://url2");
  const [r1, r2] = result;
  const r3 = yield request("http://url3");
  console.log(r3);
}
```

#### 兼容
没有生成器的兼容迭代器函数代码
```js
function foo(url) {
  let state;
  let val;
  function process(v) {
    switch(state) {
      case 1:
        console.log(url);
        return request(url); // 一个promise
      case 2:
        val = v;
        return;
      case 3:
        const err = v;
        return false;
    }
  }
  return {
    next: function(v) {
      if (!state) {
        state = 1;
        return {
          done: false,
          value: process();
        };
      } else if (state === 1) {
        state = 2;
        return {
          done: true,
          vlaue: process()
        };
      } else {
        return {
          done: true,
          value: undefined
        }；
      }
    }，
    "throw": function(e) {
      if (state === 1) {
        state = 3;
        return {
          done: true,
          value: process(),
        }
      } else {
        throw e;
      }
    }
  }
}

// 调用
const it = foo("url");
const p = it.next().value;
p.then(function(text) {
  it.next();
}, function(err) {
  it.throw(err);
});
```
